Workbook

Sheet jan22
C2: RELATÓRIO MENSAL DE ACOMPANHAMENTO DO CUSTO DO GÁS
C3: 44562
C5: Petrobras | D5: =SUMIF($C$18:$G$40,$C$5:$C$7,$G$18:$G$40)/SUMIF($C$18:$G$40,$C$5:$C$7,$E$18:$E$40) -> 2.0108289
C6: Shell | D6: =SUMIF($C$18:$G$40,$C$5:$C$7,$G$18:$G$40)/SUMIF($C$18:$G$40,$C$5:$C$7,$E$18:$E$40) -> 2.055651
C7: NFE | D7: =SUM(G33:G34)/SUM(E33:E34) -> 3.1718472
M8: Poderação QDC | N8: Poderação QDR
C9: Custo Médio Ponderado real | D9: =+G45/E45 -> 2.0452406 | L9: =+C5 -> Petrobras | M9: =790000/1580000 -> 0.5 | N9: =+SUM(E18:E31)/E45 -> 0.46550278
L10: =+C6 -> Shell | M10: 0.47468354 | N10: =+E32/E45 -> 0.5251311
C11: Custo Médio Ponderado tarifa | D11: 2.025 | L11: =+C7 -> NFE | M11: 0.025316456 | N11: =+SUM(E33:E34)/E45 -> 0.0093661186
L12: Total | M12: =SUM(M9:M11) -> 1 | N12: =SUM(N9:N11) -> 1
L16: CONFORME XML DA NOTA
B17: Mês | C17: Supridor | D17: Nota Fiscal | E17: Vol m³ | F17: Compra R$ c/tributos | G17: Compra R$ s/tributos | H17: Custo | I17: ICMS | J17: PIS | K17: COFINS | L17: ICMS | M17: PIS | N17: COFINS
B18: 44562 | C18: Petrobras | D18: 10497-6 | E18: 30483 | F18: 77719.07 | G18: =F18-SUM(L18:N18) -> 61203.768 | H18: =+IF(G18=0,0,G18/E18) -> 2.0078 | I18: 0.12 | J18: 0.0165 | K18: 0.076 | L18: =+I18*F18 -> 9326.2884 | M18: =+F18*J18 -> 1282.3647 | N18: =K18*F18 -> 5906.6493
B19: 44562 | C19: Petrobras | D19: 4820-24 | E19: 3484310 | F19: 8883552.5 | G19: =F19-SUM(L19:N19) -> 6995797.6 | H19: =+IF(G19=0,0,G19/E19) -> 2.0078 | I19: 0.12 | J19: 0.0165 | K19: 0.076 | L19: =+I19*F19 -> 1066026.3 | M19: =+F19*J19 -> 146578.62 | N19: =K19*F19 -> 675149.99
B20: 44562 | C20: Petrobras | D20: 10499-6 | E20: 3507754 | F20: 8943325 | G20: =F20-SUM(L20:N20) -> 7042868.5 | H20: =+IF(G20=0,0,G20/E20) -> 2.0078 | I20: 0.12 | J20: 0.0165 | K20: 0.076 | L20: =+I20*F20 -> 1073199 | M20: =+F20*J20 -> 147564.86 | N20: =K20*F20 -> 679692.7
B21: 44562 | C21: Petrobras | D21: 3401-12 | E21: 3129545 | F21: 7979048.2 | G21: =F21-SUM(L21:N21) -> 6283500.4 | H21: =+IF(G21=0,0,G21/E21) -> 2.0078 | I21: 0.12 | J21: 0.0165 | K21: 0.076 | L21: =+I21*F21 -> 957485.78 | M21: =+F21*J21 -> 131654.3 | N21: =K21*F21 -> 606407.66
B22: 44562 | C22: Petrobras | D22: 4758-4 | E22: 9448559 | F22: 24089926 | G22: =F22-SUM(L22:N22) -> 18970817 | H22: =+IF(G22=0,0,G22/E22) -> 2.0078 | I22: 0.12 | J22: 0.0165 | K22: 0.076 | L22: =+I22*F22 -> 2890791.1 | M22: =+F22*J22 -> 397483.78 | N22: =K22*F22 -> 1830834.4
B23: 44562 | C23: Petrobras | D23: 430266-2 | E23: 3889558 | F23: 9324721.9 | G23: =F23-SUM(L23:N23) -> 7809454.5 | H23: =+IF(G23=0,0,G23/E23) -> 2.0078 | I23: 0.07 | J23: 0.0165 | K23: 0.076 | L23: =+I23*F23 -> 652730.53 | M23: =+F23*J23 -> 153857.91 | N23: =K23*F23 -> 708678.86
B24: 44562 | C24: Petrobras | D24: 3193-28 | E24: 232008 | F24: 591524.65 | G24: =F24-SUM(L24:N24) -> 465825.66 | H24: =+IF(G24=0,0,G24/E24) -> 2.0078 | I24: 0.12 | J24: 0.0165 | K24: 0.076 | L24: =+I24*F24 -> 70982.958 | M24: =+F24*J24 -> 9760.1567 | N24: =K24*F24 -> 44955.873
B25: 44562 | C25: Petrobras | D25: 3992-4 | E25: 41095 | F25: 104775.29 | G25: =F25-SUM(L25:N25) -> 82510.541 | H25: =+IF(G25=0,0,G25/E25) -> 2.0078 | I25: 0.12 | J25: 0.0165 | K25: 0.076 | L25: =+I25*F25 -> 12573.035 | M25: =+F25*J25 -> 1728.7923 | N25: =K25*F25 -> 7962.922
B26: 44562 | C26: Petrobras | D26: 10498-6 | E26: 786 | F26: 2833.99 | G26: =F26-SUM(L26:N26) -> 2231.7671 | H26: =+IF(G26=0,0,G26/E26) -> 2.8393984 | I26: 0.12 | J26: 0.0165 | K26: 0.076 | L26: =+I26*F26 -> 340.0788 | M26: =+F26*J26 -> 46.760835 | N26: =K26*F26 -> 215.38324
B27: 44562 | C27: Petrobras | D27: 4821-24 | E27: 15676 | F27: 56521.18 | G27: =F27-SUM(L27:N27) -> 44510.429 | H27: =+IF(G27=0,0,G27/E27) -> 2.8393997 | I27: 0.12 | J27: 0.0165 | K27: 0.076 | L27: =+I27*F27 -> 6782.5416 | M27: =+F27*J27 -> 932.59947 | N27: =K27*F27 -> 4295.6097
B28: 44562 | C28: Petrobras | D28: 3402-12 | E28: 4810 | F28: 17342.87 | G28: =F28-SUM(L28:N28) -> 13657.51 | H28: =+IF(G28=0,0,G28/E28) -> 2.8393992 | I28: 0.12 | J28: 0.0165 | K28: 0.076 | L28: =+I28*F28 -> 2081.1444 | M28: =+F28*J28 -> 286.15736 | N28: =K28*F28 -> 1318.0581
B29: 44562 | C29: Petrobras | D29: 4759-4 | E29: 12211 | F29: 44027.82 | G29: =F29-SUM(L29:N29) -> 34671.908 | H29: =+IF(G29=0,0,G29/E29) -> 2.8393996 | I29: 0.12 | J29: 0.0165 | K29: 0.076 | L29: =+I29*F29 -> 5283.3384 | M29: =+F29*J29 -> 726.45903 | N29: =K29*F29 -> 3346.1143
... B31: 44562 | C31: Petrobras | D31: 10500-6 | E31: 19004 | F31: 68520.58 | G31: =F31-SUM(L31:N31) -> 53959.957 | H31: =+IF(G31=0,0,G31/E31) -> 2.8394 | I31: 0.12 | J31: 0.0165 | K31: 0.076 | L31: =+I31*F31 -> 8222.4696 | M31: =+F31*J31 -> 1130.5896 | N31: =K31*F31 -> 5207.5641
B32: 44562 | C32: Shell | D32: 14-1 | E32: 26905255 | F32: 65532528 | G32: =F32-SUM(L32:N32) -> 55307816 | H32: =+IF(G32=0,0,G32/E32) -> 2.055651 | I32: 0.07 | J32: 0.0165 | K32: 0.076 | L32: =+I32*F32 -> 4587277 | M32: =+(F32-L32)*J32 -> 1005596.6 | N32: =+(F32-L32)*K32 -> 4631839.1
B33: 44562 | C33: New Fortress (Petrolina) | D33: 9-1 | E33: 453796 | F33: 1937391.3 | G33: =F33-SUM(L33:N33) -> 1441709.7 | H33: =+IF(G33=0,0,G33/E33) -> 3.1769996 | I33: 0.18 | J33: 0.0165 | K33: 0.076 | L33: =+I33*F33 -> 348730.43 | M33: =+(F33-L33)*J33 -> 26212.904 | N33: =+(F33-L33)*K33 -> 120738.22
B34: 44562 | C34: New Fortress (Garanhuns) | D34: 3-1 | E34: 26080 | F34: 108020.75 | G34: =F34-SUM(L34:N34) -> 80383.641 | H34: =+IF(G34=0,0,G34/E34) -> 3.0821948 | I34: 0.18 | J34: 0.0165 | K34: 0.076 | L34: =+I34*F34 -> 19443.735 | M34: =+(F34-L34)*J34 -> 1461.5207 | N34: =+(F34-L34)*K34 -> 6731.8531
E45: =SUM(E18:E34) -> 51235311 | G45: =SUM(G18:G34) -> 1.0478854e+08
B48: Observações Relevantes:

Sheet fev22
C2: RELATÓRIO MENSAL DE ACOMPANHAMENTO DO CUSTO DO GÁS
C3: 44593
C5: Petrobras | D5: =SUMIF($C$18:$G$40,$C$5:$C$7,$G$18:$G$40)/SUMIF($C$18:$G$40,$C$5:$C$7,$E$18:$E$40) -> 2.3132459
C6: Shell | D6: =SUMIF($C$18:$G$40,$C$5:$C$7,$G$18:$G$40)/SUMIF($C$18:$G$40,$C$5:$C$7,$E$18:$E$40) -> 1.7200042
C7: NFE | D7: =SUM(G33:G34)/SUM(E33:E34) -> 3.4477245
M8: Poderação QDC | N8: Poderação QDR
C9: Custo Médio Ponderado real | D9: =+G45/E45 -> 2.0428354 | L9: =+C5 -> Petrobras | M9: =790000/1580000 -> 0.5 | N9: =+SUM(E18:E31)/E45 -> 0.50481329
L10: =+C6 -> Shell | M10: 0.47468354 | N10: =+E32/E45 -> 0.48166893
C11: Custo Médio Ponderado tarifa | D11: 2.025 | L11: =+C7 -> NFE | M11: 0.025316456 | N11: =+SUM(E33:E34)/E45 -> 0.01351778
L12: Total | M12: =SUM(M9:M11) -> 1 | N12: =SUM(N9:N11) -> 1
L16: CONFORME XML DA NOTA
B17: Mês | C17: Supridor | D17: Nota Fiscal | E17: Vol m³ | F17: Compra R$ c/tributos | G17: Compra R$ s/tributos | H17: Custo | I17: ICMS | J17: PIS | K17: COFINS | L17: ICMS | M17: PIS | N17: COFINS
B18: 44593 | C18: Petrobras | D18: 4879-24 | E18: 768484 | F18: 2217625.3 | G18: =F18-SUM(L18:N18) -> 1746379.9 | H18: =+IF(G18=0,0,G18/E18) -> 2.2725 | I18: 0.12 | J18: 0.0165 | K18: 0.076 | L18: =+I18*F18 -> 266115.03 | M18: =+F18*J18 -> 36590.817 | N18: =K18*F18 -> 168539.52
B19: 44593 | C19: Petrobras | D19: 3432-12 | E19: 245003 | F19: 707008.66 | G19: =F19-SUM(L19:N19) -> 556769.32 | H19: =+IF(G19=0,0,G19/E19) -> 2.2725 | I19: 0.12 | J19: 0.0165 | K19: 0.076 | L19: =+I19*F19 -> 84841.039 | M19: =+F19*J19 -> 11665.643 | N19: =K19*F19 -> 53732.658
B20: 44593 | C20: Petrobras | D20: 10595-6 | E20: 1145411 | F20: 3305328.9 | G20: =F20-SUM(L20:N20) -> 2602946.5 | H20: =+IF(G20=0,0,G20/E20) -> 2.2725 | I20: 0.12 | J20: 0.0165 | K20: 0.076 | L20: =+I20*F20 -> 396639.47 | M20: =+F20*J20 -> 54537.927 | N20: =K20*F20 -> 251205
B21: 44593 | C21: Petrobras | D21: 4813-4 | E21: 10273133 | F21: 29645327 | G21: =F21-SUM(L21:N21) -> 23345695 | H21: =+IF(G21=0,0,G21/E21) -> 2.2725 | I21: 0.12 | J21: 0.0165 | K21: 0.076 | L21: =+I21*F21 -> 3557439.2 | M21: =+F21*J21 -> 489147.89 | N21: =K21*F21 -> 2253044.8
B22: 44593 | C22: Petrobras | D22: 3245-28 | E22: 23935 | F22: 69069.57 | G22: =F22-SUM(L22:N22) -> 54392.286 | H22: =+IF(G22=0,0,G22/E22) -> 2.2725 | I22: 0.12 | J22: 0.0165 | K22: 0.076 | L22: =+I22*F22 -> 8288.3484 | M22: =+F22*J22 -> 1139.6479 | N22: =K22*F22 -> 5249.2873
B23: 44593 | C23: Petrobras | D23: 430396-2 | E23: 10337821 | F23: 28050983 | G23: =F23-SUM(L23:N23) -> 23492698 | H23: =+IF(G23=0,0,G23/E23) -> 2.2725 | I23: 0.07 | J23: 0.0165 | K23: 0.076 | L23: =+I23*F23 -> 1963568.8 | M23: =+F23*J23 -> 462841.22 | N23: =K23*F23 -> 2131874.7
B24: 44593 | C24: Petrobras | D24: 10593-6 | E24: 218638 | F24: 630926.81 | G24: =F24-SUM(L24:N24) -> 496854.86 | H24: =+IF(G24=0,0,G24/E24) -> 2.2725 | I24: 0.12 | J24: 0.0165 | K24: 0.076 | L24: =+I24*F24 -> 75711.217 | M24: =+F24*J24 -> 10410.292 | N24: =K24*F24 -> 47950.438
B25: 44593 | C25: Petrobras | D25: 430397-2 | E25: 530835 | F25: 2051336.6 | G25: =F25-SUM(L25:N25) -> 1717994.4 | H25: =+IF(G25=0,0,G25/E25) -> 3.2364 | I25: 0.07 | J25: 0.0165 | K25: 0.076 | L25: =+I25*F25 -> 143593.56 | M25: =+F25*J25 -> 33847.054 | N25: =K25*F25 -> 155901.58
B26: 44593 | C26: Petrobras | D26: 4880-24 | E26: 33870 | F26: 139196.03 | G26: =F26-SUM(L26:N26) -> 109616.87 | H26: =+IF(G26=0,0,G26/E26) -> 3.2364002 | I26: 0.12 | J26: 0.0165 | K26: 0.076 | L26: =+I26*F26 -> 16703.524 | M26: =+F26*J26 -> 2296.7345 | N26: =K26*F26 -> 10578.898
B27: 44593 | C27: Petrobras | D27: 4814-4 | E27: 379365 | F27: 1559081.8 | G27: =F27-SUM(L27:N27) -> 1227776.9 | H27: =+IF(G27=0,0,G27/E27) -> 3.2364 | I27: 0.12 | J27: 0.0165 | K27: 0.076 | L27: =+I27*F27 -> 187089.81 | M27: =+F27*J27 -> 25724.849 | N27: =K27*F27 -> 118490.21
B28: 44593 | C28: Petrobras | D28: 10596-6 | E28: 52112 | F28: 214165.43 | G28: =F28-SUM(L28:N28) -> 168655.28 | H28: =+IF(G28=0,0,G28/E28) -> 3.2364 | I28: 0.12 | J28: 0.0165 | K28: 0.076 | L28: =+I28*F28 -> 25699.852 | M28: =+F28*J28 -> 3533.7296 | N28: =K28*F28 -> 16276.573
B29: 44593 | C29: Petrobras | D29: 3246-2 | E29: 874 | F29: 3591.89 | G29: =F29-SUM(L29:N29) -> 2828.6134 | H29: =+IF(G29=0,0,G29/E29) -> 3.2363997 | I29: 0.12 | J29: 0.0165 | K29: 0.076 | L29: =+I29*F29 -> 431.0268 | M29: =+F29*J29 -> 59.266185 | N29: =K29*F29 -> 272.98364
... B31: 44593 | C31: Petrobras | D31: 4815-4 | E31: 6555 | F31: 34962.5 | G31: =F31-SUM(L31:N31) -> 27532.969 | H31: =+IF(G31=0,0,G31/E31) -> 4.2003003 | I31: 0.12 | J31: 0.0165 | K31: 0.076 | L31: =+I31*F31 -> 4195.5 | M31: =+F31*J31 -> 576.88125 | N31: =K31*F31 -> 2657.15
B32: 44593 | C32: Shell | D32: 30-1 | E32: 22919983 | F32: 46710467 | G32: =F32-SUM(L32:N32) -> 39422466 | H32: =+IF(G32=0,0,G32/E32) -> 1.7200042 | I32: 0.07 | J32: 0.0165 | K32: 0.076 | L32: =+I32*F32 -> 3269732.7 | M32: =+(F32-L32)*J32 -> 716772.12 | N32: =+(F32-L32)*K32 -> 3301495.8
B33: 44593 | C33: New Fortress (Petrolina) | D33: 10-1 | E33: 581205 | F33: 2699929.7 | G33: =F33-SUM(L33:N33) -> 2009152.7 | H33: =+IF(G33=0,0,G33/E33) -> 3.4568744 | I33: 0.18 | J33: 0.0165 | K33: 0.076 | L33: =+I33*F33 -> 485987.35 | M33: =+(F33-L33)*J33 -> 36530.049 | N33: =+(F33-L33)*K33 -> 168259.62
B34: 44593 | C34: New Fortress (Garanhuns) | D34: 9-1 | E34: 62032 | F34: 280254.37 | G34: =F34-SUM(L34:N34) -> 208551.29 | H34: =+IF(G34=0,0,G34/E34) -> 3.3619953 | I34: 0.18 | J34: 0.0165 | K34: 0.076 | L34: =+I34*F34 -> 50445.787 | M34: =+(F34-L34)*J34 -> 3791.8416 | N34: =+(F34-L34)*K34 -> 17465.452
E45: =SUM(E18:E34) -> 47584516 | G45: =SUM(G18:G34) -> 97207335
B48: Observações Relevantes:

Sheet mar22
C2: RELATÓRIO MENSAL DE ACOMPANHAMENTO DO CUSTO DO GÁS
C3: 44621
C5: Petrobras | D5: =SUMIF($C$18:$G$40,$C$5:$C$7,$G$18:$G$40)/SUMIF($C$18:$G$40,$C$5:$C$7,$E$18:$E$40) -> 2.3201778
C6: Shell | D6: =SUMIF($C$18:$G$40,$C$5:$C$7,$G$18:$G$40)/SUMIF($C$18:$G$40,$C$5:$C$7,$E$18:$E$40) -> 1.7200042
C7: NFE | D7: =SUM(G39:G40)/SUM(E39:E40) -> 3.4481454
M8: Poderação QDC | N8: Poderação QDR
C9: Custo Médio Ponderado real | D9: =+G45/E45 -> 2.0482984 | L9: =+C5 -> Petrobras | M9: =790000/1580000 -> 0.5 | N9: =+SUM(E18:E37)/E45 -> 0.50557782
L10: =+C6 -> Shell | M10: 0.47468354 | N10: =+E38/E45 -> 0.4800369
C11: Custo Médio Ponderado tarifa | D11: 2.025 | L11: =+C7 -> NFE | M11: 0.025316456 | N11: =+SUM(E39:E40)/E45 -> 0.014385275
C12: Volume de vendas | D12: ='[1]Compra 03 2022'!$C$25 -> 54546983 | L12: Total | M12: =SUM(M9:M11) -> 1 | N12: =SUM(N9:N11) -> 1
L16: CONFORME XML DA NOTA
B17: Mês | C17: Supridor | D17: Nota Fiscal | E17: Vol m³ | F17: Compra R$ c/tributos | G17: Compra R$ s/tributos | H17: Custo | I17: ICMS | J17: PIS | K17: COFINS | L17: ICMS | M17: PIS | N17: COFINS
B18: 44621 | C18: Petrobras | D18: 4874-4 | E18: 9254960 | F18: 26707170 | G18: =F18-SUM(L18:N18) -> 21031897 | H18: =+IF(G18=0,0,G18/E18) -> 2.2725 | I18: 0.12 | J18: 0.0165 | K18: 0.076 | L18: =+I18*F18 -> 3204860.4 | M18: =+F18*J18 -> 440668.31 | N18: =K18*F18 -> 2029744.9
B19: 44621 | C19: Petrobras | D19: 10723-6 | E19: 6114653 | F19: 17645142 | G19: =F19-SUM(L19:N19) -> 13895549 | H19: =+IF(G19=0,0,G19/E19) -> 2.2725 | I19: 0.12 | J19: 0.0165 | K19: 0.076 | L19: =+I19*F19 -> 2117417 | M19: =+F19*J19 -> 291144.83 | N19: =K19*F19 -> 1341030.8
B20: 44621 | C20: Petrobras | D20: 3457-12 | E20: 6603143 | F20: 19054784 | G20: =F20-SUM(L20:N20) -> 15005642 | H20: =+IF(G20=0,0,G20/E20) -> 2.2725 | I20: 0.12 | J20: 0.0165 | K20: 0.076 | L20: =+I20*F20 -> 2286574.1 | M20: =+F20*J20 -> 314403.94 | N20: =K20*F20 -> 1448163.6
B21: 44621 | C21: Petrobras | D21: 4-9 | E21: 2013407 | F21: 5463244.7 | G21: =F21-SUM(L21:N21) -> 4575467.4 | H21: =+IF(G21=0,0,G21/E21) -> 2.2725 | I21: 0.07 | J21: 0.0165 | K21: 0.076 | L21: =+I21*F21 -> 382427.13 | M21: =+F21*J21 -> 90143.537 | N21: =K21*F21 -> 415206.59
B22: 44621 | C22: Petrobras | D22: 4011-4 | E22: 842191 | F22: 2430322.6 | G22: =F22-SUM(L22:N22) -> 1913879 | H22: =+IF(G22=0,0,G22/E22) -> 2.2725 | I22: 0.12 | J22: 0.0165 | K22: 0.076 | L22: =+I22*F22 -> 291638.71 | M22: =+F22*J22 -> 40100.323 | N22: =K22*F22 -> 184704.52
B23: 44621 | C23: Petrobras | D23: 10720-6 | E23: 413670 | F23: 1193733.4 | G23: =F23-SUM(L23:N23) -> 940065.08 | H23: =+IF(G23=0,0,G23/E23) -> 2.2725 | I23: 0.12 | J23: 0.0165 | K23: 0.076 | L23: =+I23*F23 -> 143248.01 | M23: =+F23*J23 -> 19696.602 | N23: =K23*F23 -> 90723.741
B24: 44621 | C24: Petrobras | D24: 4936-24 | E24: 290491 | F24: 838274.03 | G24: =F24-SUM(L24:N24) -> 660140.8 | H24: =+IF(G24=0,0,G24/E24) -> 2.2725 | I24: 0.12 | J24: 0.0165 | K24: 0.076 | L24: =+I24*F24 -> 100592.88 | M24: =+F24*J24 -> 13831.521 | N24: =K24*F24 -> 63708.826
B25: 44621 | C25: Petrobras | D25: 4875-4 | E25: 493489 | F25: 2028098.8 | G25: =F25-SUM(L25:N25) -> 1597127.8 | H25: =+IF(G25=0,0,G25/E25) -> 3.2364 | I25: 0.12 | J25: 0.0165 | K25: 0.076 | L25: =+I25*F25 -> 243371.85 | M25: =+F25*J25 -> 33463.63 | N25: =K25*F25 -> 154135.51
B26: 44621 | C26: Petrobras | D26: 3456-12 | E26: 318441 | F26: 1308701.5 | G26: =F26-SUM(L26:N26) -> 1030602.4 | H26: =+IF(G26=0,0,G26/E26) -> 3.2364 | I26: 0.12 | J26: 0.0165 | K26: 0.076 | L26: =+I26*F26 -> 157044.18 | M26: =+F26*J26 -> 21593.575 | N26: =K26*F26 -> 99461.316
B27: 44621 | C27: Petrobras | D27: 10725-6 | E27: 210891.97 | F27: 866705.74 | G27: =F27-SUM(L27:N27) -> 682530.77 | H27: =+IF(G27=0,0,G27/E27) -> 3.2364 | I27: 0.12 | J27: 0.0165 | K27: 0.076 | L27: =+I27*F27 -> 104004.69 | M27: =+F27*J27 -> 14300.645 | N27: =K27*F27 -> 65869.636
B28: 44621 | C28: Petrobras | D28: 10726-6 | E28: 116219.03 | F28: 477627.01 | G28: =F28-SUM(L28:N28) -> 376131.27 | H28: =+IF(G28=0,0,G28/E28) -> 3.2364 | I28: 0.12 | J28: 0.0165 | K28: 0.076 | L28: =+I28*F28 -> 57315.241 | M28: =+F28*J28 -> 7880.8457 | N28: =K28*F28 -> 36299.653
B29: 44621 | C29: Petrobras | D29: 5-9 | E29: 86428 | F29: 333988.75 | G29: =F29-SUM(L29:N29) -> 279715.58 | H29: =+IF(G29=0,0,G29/E29) -> 3.2364 | I29: 0.07 | J29: 0.0165 | K29: 0.076 | L29: =+I29*F29 -> 23379.213 | M29: =+F29*J29 -> 5510.8144 | N29: =K29*F29 -> 25383.145
... B37: 44621 | C37: Petrobras | D37: 10722-6 | E37: 38 | F37: 202.68 | G37: =F37-SUM(L37:N37) -> 159.6105 | H37: =+IF(G37=0,0,G37/E37) -> 4.2002763 | I37: 0.12 | J37: 0.0165 | K37: 0.076 | L37: =+I37*F37 -> 24.3216 | M37: =+F37*J37 -> 3.34422 | N37: =K37*F37 -> 15.40368
B38: 44621 | C38: Shell | D38: 39-1 | E38: 25482782 | F38: 51933400 | G38: =F38-SUM(L38:N38) -> 43830491 | H38: =+IF(G38=0,0,G38/E38) -> 1.7200042 | I38: 0.07 | J38: 0.0165 | K38: 0.076 | L38: =+I38*F38 -> 3635338 | M38: =+(F38-L38)*J38 -> 796918.02 | N38: =+(F38-L38)*K38 -> 3670652.7
B39: 44621 | C39: New Fortress (Petrolina) | D39: 11-1 | E39: 693387 | F39: 3221060 | G39: =F39-SUM(L39:N39) -> 2396951.8 | H39: =+IF(G39=0,0,G39/E39) -> 3.4568744 | I39: 0.18 | J39: 0.0165 | K39: 0.076 | L39: =+I39*F39 -> 579790.79 | M39: =+(F39-L39)*J39 -> 43580.941 | N39: =+(F39-L39)*K39 -> 200736.46
B40: 44621 | C40: New Fortress (Garanhuns) | D40: 10-1 | E40: 70256 | F40: 317409.58 | G40: =F40-SUM(L40:N40) -> 236200.34 | H40: =+IF(G40=0,0,G40/E40) -> 3.3619953 | I40: 0.18 | J40: 0.0165 | K40: 0.076 | L40: =+I40*F40 -> 57133.724 | M40: =+(F40-L40)*J40 -> 4294.5516 | N40: =+(F40-L40)*K40 -> 19780.965
E45: =SUM(E18:E40) -> 53085048 | G45: =SUM(G18:G40) -> 1.0873402e+08
B48: Observações Relevantes:

Sheet abr22
C2: RELATÓRIO MENSAL DE ACOMPANHAMENTO DO CUSTO DO GÁS
C3: 44652
C5: Petrobras | D5: =SUMIF($C$18:$G$40,$C$5:$C$7,$G$18:$G$40)/SUMIF($C$18:$G$40,$C$5:$C$7,$E$18:$E$40) -> 2.3200881
C6: Shell | D6: =SUMIF($C$18:$G$40,$C$5:$C$7,$G$18:$G$40)/SUMIF($C$18:$G$40,$C$5:$C$7,$E$18:$E$40) -> 1.720021
C7: NFE | D7: =SUM(G35:G36)/SUM(E35:E36) -> 3.4421499
M8: Poderação QDC | N8: Poderação QDR
C9: Custo Médio Ponderado real | D9: =+G45/E45 -> 2.0403835 | L9: =+C5 -> Petrobras | M9: =790000/1580000 -> 0.5 | N9: =+SUM(E18:E33)/E45 -> 0.50813882
L10: =+C6 -> Shell | M10: 0.47468354 | N10: =+E34/E45 -> 0.48289261
C11: Custo Médio Ponderado tarifa | D11: 2.025 | L11: =+C7 -> NFE | M11: 0.025316456 | N11: =+SUM(E35:E36)/E45 -> 0.0089685688
L12: Total | M12: =SUM(M9:M11) -> 1 | N12: =SUM(N9:N11) -> 1
L16: CONFORME XML DA NOTA
B17: Mês | C17: Supridor | D17: Nota Fiscal | E17: Vol m³ | F17: Compra R$ c/tributos | G17: Compra R$ s/tributos | H17: Custo | I17: ICMS | J17: PIS | K17: COFINS | L17: ICMS | M17: PIS | N17: COFINS
B18: 44652 | C18: Petrobras | D18: 4946-24 | E18: 2640756 | F18: 7620467.3 | G18: =F18-SUM(L18:N18) -> 6001118 | H18: =+IF(G18=0,0,G18/E18) -> 2.2725 | I18: 0.12 | J18: 0.0165 | K18: 0.076 | L18: =+I18*F18 -> 914456.08 | M18: =+F18*J18 -> 125737.71 | N18: =K18*F18 -> 579155.52
B19: 44652 | C19: Petrobras | D19: 10774-6 | E19: 165324 | F19: 477077.83 | G19: =F19-SUM(L19:N19) -> 375698.79 | H19: =+IF(G19=0,0,G19/E19) -> 2.2725 | I19: 0.12 | J19: 0.0165 | K19: 0.076 | L19: =+I19*F19 -> 57249.34 | M19: =+F19*J19 -> 7871.7842 | N19: =K19*F19 -> 36257.915
B20: 44652 | C20: Petrobras | D20: 10776-6 | E20: 4839057 | F20: 13964136 | G20: =F20-SUM(L20:N20) -> 10996757 | H20: =+IF(G20=0,0,G20/E20) -> 2.2725 | I20: 0.12 | J20: 0.0165 | K20: 0.076 | L20: =+I20*F20 -> 1675696.3 | M20: =+F20*J20 -> 230408.24 | N20: =K20*F20 -> 1061274.3
B21: 44652 | C21: Petrobras | D21: 3288-28 | E21: 142068 | F21: 409967.66 | G21: =F21-SUM(L21:N21) -> 322849.53 | H21: =+IF(G21=0,0,G21/E21) -> 2.2725 | I21: 0.12 | J21: 0.0165 | K21: 0.076 | L21: =+I21*F21 -> 49196.119 | M21: =+F21*J21 -> 6764.4664 | N21: =K21*F21 -> 31157.542
B22: 44652 | C22: Petrobras | D22: 4914-4 | E22: 4593055 | F22: 13254244 | G22: =F22-SUM(L22:N22) -> 10437717 | H22: =+IF(G22=0,0,G22/E22) -> 2.2725 | I22: 0.12 | J22: 0.0165 | K22: 0.076 | L22: =+I22*F22 -> 1590509.3 | M22: =+F22*J22 -> 218695.03 | N22: =K22*F22 -> 1007322.6
B23: 44652 | C23: Petrobras | D23: 61-9 | E23: 12439043 | F23: 33752508 | G23: =F23-SUM(L23:N23) -> 28267725 | H23: =+IF(G23=0,0,G23/E23) -> 2.2725 | I23: 0.07 | J23: 0.0165 | K23: 0.076 | L23: =+I23*F23 -> 2362675.5 | M23: =+F23*J23 -> 556916.38 | N23: =K23*F23 -> 2565190.6
B24: 44652 | C24: Petrobras | D24: 10775-6 | E24: 588 | F24: 2416.51 | G24: =F24-SUM(L24:N24) -> 1903.0016 | H24: =+IF(G24=0,0,G24/E24) -> 3.2363973 | I24: 0.12 | J24: 0.0165 | K24: 0.076 | L24: =+I24*F24 -> 289.9812 | M24: =+F24*J24 -> 39.872415 | N24: =K24*F24 -> 183.65476
B25: 44652 | C25: Petrobras | D25: 3289-28 | E25: 10908 | F25: 44828.76 | G25: =F25-SUM(L25:N25) -> 35302.649 | H25: =+IF(G25=0,0,G25/E25) -> 3.2363998 | I25: 0.12 | J25: 0.0165 | K25: 0.076 | L25: =+I25*F25 -> 5379.4512 | M25: =+F25*J25 -> 739.67454 | N25: =K25*F25 -> 3406.9858
B26: 44652 | C26: Petrobras | D26: 4947-24 | E26: 116437 | F26: 478522.81 | G26: =F26-SUM(L26:N26) -> 376836.71 | H26: =+IF(G26=0,0,G26/E26) -> 3.2364001 | I26: 0.12 | J26: 0.0165 | K26: 0.076 | L26: =+I26*F26 -> 57422.737 | M26: =+F26*J26 -> 7895.6264 | N26: =K26*F26 -> 36367.734
B27: 44652 | C27: Petrobras | D27: 62-9 | E27: 657365 | F27: 2540293.8 | G27: =F27-SUM(L27:N27) -> 2127496.1 | H27: =+IF(G27=0,0,G27/E27) -> 3.2364 | I27: 0.07 | J27: 0.0165 | K27: 0.076 | L27: =+I27*F27 -> 177820.57 | M27: =+F27*J27 -> 41914.848 | N27: =K27*F27 -> 193062.33
B28: 44652 | C28: Petrobras | D28: 10777-6 | E28: 200808 | F28: 825263.5 | G28: =F28-SUM(L28:N28) -> 649895.01 | H28: =+IF(G28=0,0,G28/E28) -> 3.2364 | I28: 0.12 | J28: 0.0165 | K28: 0.076 | L28: =+I28*F28 -> 99031.62 | M28: =+F28*J28 -> 13616.848 | N28: =K28*F28 -> 62720.026
B29: 44652 | C29: Petrobras | D29: 4915-4 | E29: 204847 | F29: 841862.64 | G29: =F29-SUM(L29:N29) -> 662966.83 | H29: =+IF(G29=0,0,G29/E29) -> 3.2364 | I29: 0.12 | J29: 0.0165 | K29: 0.076 | L29: =+I29*F29 -> 101023.52 | M29: =+F29*J29 -> 13890.734 | N29: =K29*F29 -> 63981.561
... B33: 44652 | C33: Petrobras | D33: 4948-24 | E33: 18055 | F33: 96300.22 | G33: =F33-SUM(L33:N33) -> 75836.423 | H33: =+IF(G33=0,0,G33/E33) -> 4.2003004 | I33: 0.12 | J33: 0.0165 | K33: 0.076 | L33: =+I33*F33 -> 11556.026 | M33: =+F33*J33 -> 1588.9536 | N33: =K33*F33 -> 7318.8167
B34: 44652 | C34: Shell | D34: 54-1 | E34: 24763368 | F34: 50467744 | G34: =F34-SUM(L34:N34) -> 42593514 | H34: =+IF(G34=0,0,G34/E34) -> 1.720021 | I34: 0.07 | J34: 0.0165 | K34: 0.076 | L34: =+I34*F34 -> 3532742.1 | M34: =+(F34-L34)*J34 -> 774427.53 | N34: =+(F34-L34)*K34 -> 3567060.1
B35: 44652 | C35: New Fortress (Petrolina) | D35: 13-1 | E35: 388544 | F35: 1804942.3 | G35: =F35-SUM(L35:N35) -> 1343147.8 | H35: =+IF(G35=0,0,G35/E35) -> 3.4568744 | I35: 0.18 | J35: 0.0165 | K35: 0.076 | L35: =+I35*F35 -> 324889.61 | M35: =+(F35-L35)*J35 -> 24420.869 | N35: =+(F35-L35)*K35 -> 112484
B36: 44652 | C36: New Fortress (Garanhuns) | D36: 11-1 | E36: 71376 | F36: 322469.63 | G36: =F36-SUM(L36:N36) -> 239965.78 | H36: =+IF(G36=0,0,G36/E36) -> 3.3619953 | I36: 0.18 | J36: 0.0165 | K36: 0.076 | L36: =+I36*F36 -> 58044.533 | M36: =+(F36-L36)*J36 -> 4363.0141 | N36: =+(F36-L36)*K36 -> 20096.307
E45: =SUM(E18:E40) -> 51281315 | G45: =SUM(G18:G40) -> 1.0463355e+08
B48: Observações Relevantes:

Sheet mai22
C2: RELATÓRIO MENSAL DE ACOMPANHAMENTO DO CUSTO DO GÁS
C3: 44682
C5: Petrobras | D5: =SUMIF($C$18:$G$40,$C$5:$C$7,$G$18:$G$40)/SUMIF($C$18:$G$40,$C$5:$C$7,$E$18:$E$40) -> 2.7753623
C6: Shell | D6: =SUMIF($C$18:$G$40,$C$5:$C$7,$G$18:$G$40)/SUMIF($C$18:$G$40,$C$5:$C$7,$E$18:$E$40) -> 1.9547305
C7: NFE | D7: =SUM(G29:G30)/SUM(E29:E30) -> 3.8550713
M8: Poderação QDC | N8: Poderação QDR
C9: Custo Médio Ponderado real | D9: =+G45/E45 -> 2.3944805 | L9: =+C5 -> Petrobras | M9: =790000/1580000 -> 0.5 | N9: =+SUM(E18:E27)/E45 -> 0.50457814
L10: =+C6 -> Shell | M10: 0.47468354 | N10: =+E28/E45 -> 0.48190998
C11: Custo Médio Ponderado tarifa | D11: 2.3639 | L11: =+C7 -> NFE | M11: 0.025316456 | N11: =+SUM(E29:E30)/E45 -> 0.013511873
L12: Total | M12: =SUM(M9:M11) -> 1 | N12: z
L16: CONFORME XML DA NOTA
B17: Mês | C17: Supridor | D17: Nota Fiscal | E17: Vol m³ | F17: Compra R$ c/tributos | G17: Compra R$ s/tributos | H17: Custo | I17: ICMS | J17: PIS | K17: COFINS | L17: ICMS | M17: PIS | N17: COFINS
B18: 44682 | C18: Petrobras | D18: 4973-4 | E18: 12806648 | F18: 43445744 | G18: =F18-SUM(L18:N18) -> 34695814 | H18: =+IF(G18=0,0,G18/E18) -> 2.7092034 | I18: 0.12 | J18: 0.0165 | K18: 0.076 | L18: =+I18*F18 -> 5213489.2 | M18: =+(F18-L18)*J18 -> 630832.2 | N18: 2905607.9
B19: 44682 | C19: Petrobras | D19: 3489-12 | E19: 8529281 | F19: 28935046 | G19: =F19-SUM(L19:N19) -> 23107557 | H19: =+IF(G19=0,0,G19/E19) -> 2.7092034 | I19: 0.12 | J19: 0.0165 | K19: 0.076 | L19: =+I19*F19 -> 3472205.6 | M19: =+(F19-L19)*J19 -> 420136.87 | N19: 1935147
B20: 44682 | C20: Petrobras | D20: 10869-6 | E20: 2998823 | F20: 10173317 | G20: =F20-SUM(L20:N20) -> 8124421.4 | H20: =+IF(G20=0,0,G20/E20) -> 2.7092034 | I20: 0.12 | J20: 0.0165 | K20: 0.076 | L20: =+I20*F20 -> 1220798.1 | M20: =+(F20-L20)*J20 -> 147716.57 | N20: 680381.29
B21: 44682 | C21: Petrobras | D21: 5000-24 | E21: 941367 | F21: 3193528 | G21: =F21-SUM(L21:N21) -> 2550354.7 | H21: =+IF(G21=0,0,G21/E21) -> 2.7092034 | I21: 0.12 | J21: 0.0165 | K21: 0.076 | L21: =+I21*F21 -> 383223.36 | M21: =+(F21-L21)*J21 -> 46370.027 | N21: 213579.96
B22: 44682 | C22: Petrobras | D22: 4974-4 | E22: 766491 | F22: 3710561.2 | G22: =F22-SUM(L22:N22) -> 2963257.9 | H22: =+IF(G22=0,0,G22/E22) -> 3.8660048 | I22: 0.12 | J22: 0.0165 | K22: 0.076 | L22: =+I22*F22 -> 445267.35 | M22: =+(F22-L22)*J22 -> 53877.349 | N22: 248158.63
B23: 44682 | C23: Petrobras | D23: 3490-12 | E23: 488627 | F23: 2365429.5 | G23: =F23-SUM(L23:N23) -> 1889034.3 | H23: =+IF(G23=0,0,G23/E23) -> 3.8660048 | I23: 0.12 | J23: 0.0165 | K23: 0.076 | L23: =+I23*F23 -> 283851.54 | M23: =+(F23-L23)*J23 -> 34346.036 | N23: 158197.56
B24: 44682 | C24: Petrobras | D24: 10870-6 | E24: 87040 | F24: 421358.18 | G24: =F24-SUM(L24:N24) -> 336497.07 | H24: =+IF(G24=0,0,G24/E24) -> 3.8660049 | I24: 0.12 | J24: 0.0165 | K24: 0.076 | L24: =+I24*F24 -> 50562.982 | M24: =+(F24-L24)*J24 -> 6118.1208 | N24: 28180.01
B25: 44682 | C25: Petrobras | D25: 5001-24 | E25: 26303 | F25: 127332.08 | G25: =F25-SUM(L25:N25) -> 101687.53 | H25: =+IF(G25=0,0,G25/E25) -> 3.866005 | I25: 0.12 | J25: 0.0165 | K25: 0.076 | L25: =+I25*F25 -> 15279.85 | M25: =+(F25-L25)*J25 -> 1848.8618 | N25: 8515.84
B26: 44682 | C26: Petrobras | D26: 3491-12 | E26: 52734 | F26: 331664.24 | G26: =F26-SUM(L26:N26) -> 264867.4 | H26: =+IF(G26=0,0,G26/E26) -> 5.0227063 | I26: 0.12 | J26: 0.0165 | K26: 0.076 | L26: =+I26*F26 -> 39799.709 | M26: =+(F26-L26)*J26 -> 4815.7648 | N26: 22181.37
B27: 44682 | C27: Petrobras | D27: 4975-4 | E27: 27244 | F27: 171347.91 | G27: =F27-SUM(L27:N27) -> 136838.61 | H27: =+IF(G27=0,0,G27/E27) -> 5.0227063 | I27: 0.12 | J27: 0.0165 | K27: 0.076 | L27: =+I27*F27 -> 20561.749 | M27: =+(F27-L27)*J27 -> 2487.9717 | N27: 11459.58
B28: 44682 | C28: Shell | D28: 74-1 | E28: 25523958 | F28: 59116039 | G28: =F28-SUM(L28:N28) -> 49892459 | H28: =+IF(G28=0,0,G28/E28) -> 1.9547305 | I28: 0.07 | J28: 0.0165 | K28: 0.076 | L28: =+I28*F28 -> 4138122.7 | M28: =+(F28-L28)*J28 -> 907135.62 | N28: =+(F28-L28)*K28 -> 4178321.6
B29: 44682 | C29: New Fortress (Petrolina) | D29: 16-1 | E29: 643817 | F29: 3343534.8 | G29: =F29-SUM(L29:N29) -> 2488091.4 | H29: =+IF(G29=0,0,G29/E29) -> 3.8645942 | I29: 0.18 | J29: 0.0165 | K29: 0.076 | L29: =+I29*F29 -> 601836.27 | M29: =+(F29-L29)*J29 -> 45238.026 | N29: =+(F29-L29)*K29 -> 208369.09
B30: 44682 | C30: New Fortress (Garanhuns) | D30: 13-1 | E30: 71828 | F30: 363866.28 | G30: =F30-SUM(L30:N30) -> 270771.09 | H30: =+IF(G30=0,0,G30/E30) -> 3.769715 | I30: 0.18 | J30: 0.0165 | K30: 0.076 | L30: =+I30*F30 -> 65495.93 | M30: =+(F30-L30)*J30 -> 4923.1108 | N30: =+(F30-L30)*K30 -> 22676.147
E45: =SUM(E18:E40) -> 52964161 | G45: =SUM(G18:G40) -> 1.2682165e+08
B48: Observações Relevantes:

Sheet jun22
C2: RELATÓRIO MENSAL DE ACOMPANHAMENTO DO CUSTO DO GÁS
C3: 44713
C5: Petrobras | D5: =SUMIF($C$18:$G$40,$C$5:$C$7,$G$18:$G$40)/SUMIF($C$18:$G$40,$C$5:$C$7,$E$18:$E$40) -> 2.7840492
C6: Shell | D6: =SUMIF($C$18:$G$40,$C$5:$C$7,$G$18:$G$40)/SUMIF($C$18:$G$40,$C$5:$C$7,$E$18:$E$40) -> 1.9547305
C7: NFE | D7: =SUM(G41:G42)/SUM(E41:E42) -> 3.7897486
M8: Poderação QDC | N8: Poderação QDR
C9: Custo Médio Ponderado real | D9: =+G45/E45 -> 2.3983039 | L9: =+C5 -> Petrobras | M9: =790000/1580000 -> 0.5 | N9: =+SUM(E18:E39)/E45 -> 0.50638886
L10: =+C6 -> Shell | M10: 0.47468354 | N10: =+E40/E45 -> 0.4807417
C11: Custo Médio Ponderado tarifa | D11: 2.3639 | L11: =+C7 -> NFE | M11: 0.025316456 | N11: =+SUM(E41:E42)/E45 -> 0.012869441
L12: Total | M12: =SUM(M9:M11) -> 1 | N12: =SUM(N9:N11) -> 1
L16: CONFORME XML DA NOTA
B17: Mês | C17: Supridor | D17: Nota Fiscal | E17: Vol m³ | F17: Compra R$ c/tributos | G17: Compra R$ s/tributos | H17: Custo | I17: ICMS | J17: PIS | K17: COFINS | L17: ICMS | M17: PIS | N17: COFINS
B18: 44713 | C18: Petrobras | D18: 3350-28 | E18: 20353 | F18: 69046.27 | G18: =F18-SUM(L18:N18) -> 55140.416 | H18: =+IF(G18=0,0,G18/E18) -> 2.7092033 | I18: 0.12 | J18: 0.0165 | K18: 0.076 | L18: =+I18*F18 -> 8285.5524 | M18: =+(F18-L18)*J18 -> 1002.5518 | N18: 4617.75
B19: 44713 | C19: Petrobras | D19: 5029-4 | E19: 6151282 | F19: 20867835 | G19: =F19-SUM(L19:N19) -> 16665074 | H19: =+IF(G19=0,0,G19/E19) -> 2.7092034 | I19: 0.12 | J19: 0.0165 | K19: 0.076 | L19: =+I19*F19 -> 2504140.2 | M19: =+(F19-L19)*J19 -> 303000.97 | N19: 1395619.9
B20: 44713 | C20: Petrobras | D20: 10928-6 | E20: 227433 | F20: 771552.07 | G20: =F20-SUM(L20:N20) -> 616162.26 | H20: =+IF(G20=0,0,G20/E20) -> 2.7092034 | I20: 0.12 | J20: 0.0165 | K20: 0.076 | L20: =+I20*F20 -> 92586.248 | M20: =+(F20-L20)*J20 -> 11202.936 | N20: 51600.63
B21: 44713 | C21: Petrobras | D21: 3519-12 | E21: 14345444 | F21: 48666012 | G21: =F21-SUM(L21:N21) -> 38864726 | H21: =+IF(G21=0,0,G21/E21) -> 2.7092034 | I21: 0.12 | J21: 0.0165 | K21: 0.076 | L21: =+I21*F21 -> 5839921.4 | M21: =+(F21-L21)*J21 -> 706630.49 | N21: 3254734.2
B22: 44713 | C22: Petrobras | D22: 5032-24 | E22: 109597 | F22: 371800.9 | G22: =F22-SUM(L22:N22) -> 296920.57 | H22: =+IF(G22=0,0,G22/E22) -> 2.7092034 | I22: 0.12 | J22: 0.0165 | K22: 0.076 | L22: =+I22*F22 -> 44616.108 | M22: =+(F22-L22)*J22 -> 5398.5491 | N22: 24865.67
B23: 44713 | C23: Petrobras | D23: 5033-24 | E23: 563591 | F23: 1911946.8 | G23: =F23-SUM(L23:N23) -> 1652249 | H23: =+IF(G23=0,0,G23/E23) -> 2.9316455 | I23: 0.12 | J23: 0.0165 | K23: 0.076 | L23: =+I23*F23 -> 229433.62 | M23: 5398.5491 | N23: 24865.67
B24: 44713 | C24: Petrobras | D24: 5030-24 | E24: 58944 | F24: 285346.23 | G24: =F24-SUM(L24:N24) -> 227877.79 | H24: =+IF(G24=0,0,G24/E24) -> 3.8660048 | I24: 0.12 | J24: 0.0165 | K24: 0.076 | L24: =+I24*F24 -> 34241.548 | M24: =+(F24-L24)*J24 -> 4143.2273 | N24: 19083.67
B25: 44713 | C25: Petrobras | D25: 3351-28 | E25: 1670 | F25: 8084.42 | G25: =F25-SUM(L25:N25) -> 6456.2238 | H25: =+IF(G25=0,0,G25/E25) -> 3.8660023 | I25: 0.12 | J25: 0.0165 | K25: 0.076 | L25: =+I25*F25 -> 970.1304 | M25: =+(F25-L25)*J25 -> 117.38578 | N25: 540.68
B26: 44713 | C26: Petrobras | D26: 5030-4 | E26: 283958 | F26: 1374632.6 | G26: =F26-SUM(L26:N26) -> 1097783 | H26: =+IF(G26=0,0,G26/E26) -> 3.8660048 | I26: 0.12 | J26: 0.0165 | K26: 0.076 | L26: =+I26*F26 -> 164955.92 | M26: =+(F26-L26)*J26 -> 19959.666 | N26: 91934.06
B27: 44713 | C27: Petrobras | D27: 10929-6 | E27: 11500 | F27: 55671.17 | G27: =F27-SUM(L27:N27) -> 44459.054 | H27: =+IF(G27=0,0,G27/E27) -> 3.8660047 | I27: 0.12 | J27: 0.0165 | K27: 0.076 | L27: =+I27*F27 -> 6680.5404 | M27: =+(F27-L27)*J27 -> 808.34539 | N27: 3723.23
B28: 44713 | C28: Petrobras | D28: 3520-12 | E28: 929102 | F28: 4497756.5 | G28: =F28-SUM(L28:N28) -> 3591912.8 | H28: =+IF(G28=0,0,G28/E28) -> 3.8660048 | I28: 0.12 | J28: 0.0165 | K28: 0.076 | L28: =+I28*F28 -> 539730.78 | M28: =+(F28-L28)*J28 -> 65307.424 | N28: 300805.46
B29: 44713 | C29: Petrobras | D29: 3352-28 | E29: 287 | F29: 1805.05 | G29: =F29-SUM(L29:N29) -> 1441.5147 | H29: =+IF(G29=0,0,G29/E29) -> 5.0226992 | I29: 0.12 | J29: 0.0165 | K29: 0.076 | L29: =+I29*F29 -> 216.606 | M29: =+(F29-L29)*J29 -> 26.209326 | N29: 120.72
B30: 44713 | C30: Petrobras | D30: 5031-24 | E30: 13231 | F30: 83214.8 | G30: =F30-SUM(L30:N30) -> 66455.425 | H30: =+IF(G30=0,0,G30/E30) -> 5.0227062 | I30: 0.12 | J30: 0.0165 | K30: 0.076 | L30: =+I30*F30 -> 9985.776 | M30: =+(F30-L30)*J30 -> 1208.2789 | N30: 5565.32
B31: 44713 | C31: Petrobras | D31: 5031-4 | E31: 2486 | F31: 15635.4 | G31: =F31-SUM(L31:N31) -> 12486.446 | H31: =+IF(G31=0,0,G31/E31) -> 5.0227055 | I31: 0.12 | J31: 0.0165 | K31: 0.076 | L31: =+I31*F31 -> 1876.248 | M31: =+(F31-L31)*J31 -> 227.02601 | N31: 1045.68
B32: 44713 | C32: Petrobras | D32: 3521-12 | E32: 48713 | F32: 306374.64 | G32: =F32-SUM(L32:N32) -> 244671.09 | H32: =+IF(G32=0,0,G32/E32) -> 5.0227063 | I32: 0.12 | J32: 0.0165 | K32: 0.076 | L32: =+I32*F32 -> 36764.957 | M32: =+(F32-L32)*J32 -> 4448.5598 | N32: 20490.03
B33: 44713 | C33: Petrobras | D33: 10927-6 | E33: 21232 | F33: 93276.03 | G33: =F33-SUM(L33:N33) -> 82082.906 | H33: =+IF(G33=0,0,G33/E33) -> 3.8659997 | I33: 0.12 | J33: 0 | K33: 0 | L33: =+I33*F33 -> 11193.124 | M33: =+(F33-L33)*J33 -> 0 | N33: 0
B34: 44713 | C34: Petrobras | D34: 3517-12 | E34: 104303 | F34: 458222.05 | G34: =F34-SUM(L34:N34) -> 403235.4 | H34: =+IF(G34=0,0,G34/E34) -> 3.8660001 | I34: 0.12 | J34: 0 | K34: 0 | L34: =+I34*F34 -> 54986.646 | M34: =+(F34-L34)*J34 -> 0 | N34: 0
B35: 44713 | C35: Petrobras | D35: 5028-4 | E35: 30694 | F35: 134844.32 | G35: =F35-SUM(L35:N35) -> 118663 | H35: =+IF(G35=0,0,G35/E35) -> 3.8659999 | I35: 0.12 | J35: 0 | K35: 0 | L35: =+I35*F35 -> 16181.318 | M35: =+(F35-L35)*J35 -> 0 | N35: 0
... B39: 44713 | C39: Petrobras | D39: 10926-6 | E39: 414365 | F39: 1275679.2 | G39: =F39-SUM(L39:N39) -> 1122597.7 | H39: =+IF(G39=0,0,G39/E39) -> 2.7092 | I39: 0.12 | J39: 0 | K39: 0 | L39: =+I39*F39 -> 153081.5 | M39: =+(F39-L39)*J39 -> 0 | N39: 0
B40: 44713 | C40: Shell | D40: 80-1 | E40: 24961813 | F40: 57814055 | G40: =F40-SUM(L40:N40) -> 48793617 | H40: =+IF(G40=0,0,G40/E40) -> 1.9547305 | I40: 0.07 | J40: 0.0165 | K40: 0.076 | L40: =+I40*F40 -> 4046983.9 | M40: =+(F40-L40)*J40 -> 887156.68 | N40: =+(F40-L40)*K40 -> 4086297.4
B41: 44713 | C41: New Fortress (Petrolina) | D41: 17-1 | E41: 608037 | F41: 3103641.7 | G41: =F41-SUM(L41:N41) -> 2309575 | H41: =+IF(G41=0,0,G41/E41) -> 3.7984119 | I41: 0.18 | J41: 0.0165 | K41: 0.076 | L41: =+I41*F41 -> 558655.51 | M41: =+(F41-L41)*J41 -> 41992.273 | N41: =+(F41-L41)*K41 -> 193418.95
B42: 44713 | C42: New Fortress (Garanhuns) | D42: 16-1 | E42: 60190 | F42: 299452.14 | G42: =F42-SUM(L42:N42) -> 222837.32 | H42: =+IF(G42=0,0,G42/E42) -> 3.7022316 | I42: 0.18 | J42: 0.0165 | K42: 0.076 | L42: =+I42*F42 -> 53901.385 | M42: =+(F42-L42)*J42-0.01 -> 4051.5775 | N42: =+(F42-L42)*K42 -> 18661.857
E45: =SUM(E18:E44) -> 51923544 | G45: =SUM(G18:G44) -> 1.2452844e+08
B48: Observações Relevantes: Publicação da Lei Complementar 194/2022, no DOU de 23.06.2022, Edição Extra, prevendo, até 31.12.2022, redução a zero da alíquota de PIS/COFINS incidente sobre a receita ou o faturamento na venda de gás natural veicular classificado nos códigos 2711.11.00 ou 2711.21.00 da NCM. "Art. 9º-B Até 31 de dezembro de 2022, ficam reduzidas a 0 (zero) as alíquotas das contribuições de que tratam o caput e o § 1º do art. 9º desta Lei Complementar incidentes sobre a receita ou o faturamento na venda ou sobre a importação de gás natural veicular classificado nos códigos 2711.11.00 ou 2711.21.00 da NCM." Dessa forma, a Copergás informou a Petrobras todo o volume de GNV e GNC veicular comercializado a partir do dia 23/06/2022, o qual foi sensibilizado nas notas do supridor e, consequentemente, foram emitidas com alíquotas zero de PIS/Cofins

Sheet jul22
C2: RELATÓRIO MENSAL DE ACOMPANHAMENTO DO CUSTO DO GÁS
C3: 44743
C5: Petrobras | D5: =SUMIF($C$18:$G$40,$C$5:$C$7,$G$18:$G$40)/SUMIF($C$18:$G$40,$C$5:$C$7,$E$18:$E$40) -> 2.7445427
C6: Shell | D6: =SUMIF($C$18:$G$40,$C$5:$C$7,$G$18:$G$40)/SUMIF($C$18:$G$40,$C$5:$C$7,$E$18:$E$40) -> 1.9547306
C7: NFE | D7: =SUM(G41:G42)/SUM(E41:E42) -> 3.749814
M8: Poderação QDC | N8: Poderação QDR
C9: Custo Médio Ponderado real | D9: =+G45/E45 -> 2.3740817 | L9: =+C5 -> Petrobras | M9: =790000/1580000 -> 0.5 | N9: =+SUM(E18:E37)/E45 -> 0.4997238
L10: =+C6 -> Shell | M10: 0.47468354 | N10: =+SUM(E38:E40)/E45 -> 0.48653689
C11: Custo Médio Ponderado tarifa | D11: 2.3639 | L11: =+C7 -> NFE | M11: 0.025316456 | N11: =+SUM(E41:E42)/E45 -> 0.013739309
L12: Total | M12: =SUM(M9:M11) -> 1 | N12: =SUM(N9:N11) -> 1
L16: CONFORME XML DA NOTA
B17: Mês | C17: Supridor | D17: Nota Fiscal | E17: Vol m³ | F17: Compra R$ c/tributos | G17: Compra R$ s/tributos | H17: Custo | I17: ICMS | J17: PIS | K17: COFINS | L17: ICMS | M17: PIS | N17: COFINS
B18: 44743 | C18: Petrobras | D18: 3597 | E18: 3815 | F18: 18468.31 | G18: =F18-SUM(L18:N18) -> 14748.813 | H18: =+IF(G18=0,0,G18/E18) -> 3.866006 | I18: 0.12 | J18: 0.0165 | K18: 0.076 | L18: =+I18*F18 -> 2216.1972 | M18: =(F18-L18)*J18 -> 268.15986 | N18: 1235.14
B19: 44743 | C19: Petrobras | D19: 3598 | E19: 484767 | F19: 1492421.3 | G19: =F19-SUM(L19:N19) -> 1313330.8 | H19: =+IF(G19=0,0,G19/E19) -> 2.7092 | I19: 0.12 | J19: 0 | K19: 0 | L19: =+I19*F19 -> 179090.56 | M19: =(F19-L19)*J19 -> 0 | N19: =(F19-L19)*K19 -> 0
B20: 44743 | C20: Petrobras | D20: 3599 | E20: 14204 | F20: 62400.75 | G20: =F20-SUM(L20:N20) -> 54912.66 | H20: =+IF(G20=0,0,G20/E20) -> 3.8659997 | I20: 0.12 | J20: 0 | K20: 0 | L20: =+I20*F20 -> 7488.09 | M20: =(F20-L20)*J20 -> 0 | N20: =(F20-L20)*K20 -> 0
B21: 44743 | C21: Petrobras | D21: 3600 | E21: 135427 | F21: 459427.54 | G21: =F21-SUM(L21:N21) -> 366899.3 | H21: =+IF(G21=0,0,G21/E21) -> 2.7092035 | I21: 0.12 | J21: 0.0165 | K21: 0.076 | L21: =+I21*F21 -> 55131.305 | M21: =(F21-L21)*J21 -> 6670.8879 | N21: 30726.05
B22: 44743 | C22: Petrobras | D22: 4049 | E22: 151815 | F22: 515022.79 | G22: =F22-SUM(L22:N22) -> 411297.71 | H22: =+IF(G22=0,0,G22/E22) -> 2.7092034 | I22: 0.12 | J22: 0.0165 | K22: 0.076 | L22: =+I22*F22 -> 61802.735 | M22: =(F22-L22)*J22 -> 7478.1309 | N22: 34444.21
B23: 44743 | C23: Petrobras | D23: 4050 | E23: 942 | F23: 4560.19 | G23: =F23-SUM(L23:N23) -> 3641.7732 | H23: =+IF(G23=0,0,G23/E23) -> 3.8660013 | I23: 0.12 | J23: 0.0165 | K23: 0.076 | L23: =+I23*F23 -> 547.2228 | M23: =(F23-L23)*J23 -> 66.213959 | N23: 304.98
B24: 44743 | C24: Petrobras | D24: 4051 | E24: 59933 | F24: 184511.91 | G24: =F24-SUM(L24:N24) -> 162370.48 | H24: =+IF(G24=0,0,G24/E24) -> 2.7092 | I24: 0.12 | J24: 0 | K24: 0 | L24: =+I24*F24 -> 22141.429 | M24: =(F24-L24)*J24 -> 0 | N24: =(F24-L24)*K24 -> 0
B25: 44743 | C25: Petrobras | D25: 4052 | E25: 372 | F25: 1634.26 | G25: =F25-SUM(L25:N25) -> 1438.1488 | H25: =+IF(G25=0,0,G25/E25) -> 3.8659914 | I25: 0.12 | J25: 0 | K25: 0 | L25: =+I25*F25 -> 196.1112 | M25: =(F25-L25)*J25 -> 0 | N25: =(F25-L25)*K25 -> 0
B26: 44743 | C26: Petrobras | D26: 11015 | E26: 2217455 | F26: 7522575.9 | G26: =F26-SUM(L26:N26) -> 6007536.6 | H26: =+IF(G26=0,0,G26/E26) -> 2.7092034 | I26: 0.12 | J26: 0.0165 | K26: 0.076 | L26: =+I26*F26 -> 902709.1 | M26: =(F26-L26)*J26 -> 109227.8 | N26: 503102.35
B27: 44743 | C27: Petrobras | D27: 11016 | E27: 69162 | F27: 334811.28 | G27: =F27-SUM(L27:N27) -> 267380.63 | H27: =+IF(G27=0,0,G27/E27) -> 3.8660048 | I27: 0.12 | J27: 0.0165 | K27: 0.076 | L27: =+I27*F27 -> 40177.354 | M27: =(F27-L27)*J27 -> 4861.4598 | N27: 22391.84
B28: 44743 | C28: Petrobras | D28: 11017 | E28: 3543910 | F28: 10910410 | G28: =F28-SUM(L28:N28) -> 9601161 | H28: =+IF(G28=0,0,G28/E28) -> 2.7092 | I28: 0.12 | J28: 0 | K28: 0 | L28: =+I28*F28 -> 1309249.2 | M28: =(F28-L28)*J28 -> 0 | N28: =(F28-L28)*K28 -> 0
B29: 44743 | C29: Petrobras | D29: 11018 | E29: 103352 | F29: 454044.13 | G29: =F29-SUM(L29:N29) -> 399558.83 | H29: =+IF(G29=0,0,G29/E29) -> 3.866 | I29: 0.12 | J29: 0 | K29: 0 | L29: =+I29*F29 -> 54485.296 | M29: =(F29-L29)*J29 -> 0 | N29: =(F29-L29)*K29 -> 0
B30: 44743 | C30: Petrobras | D30: 5106 | E30: 8325077 | F30: 28242297 | G30: =F30-SUM(L30:N30) -> 22554327 | H30: =+IF(G30=0,0,G30/E30) -> 2.7092034 | I30: 0.12 | J30: 0.0165 | K30: 0.076 | L30: =+I30*F30 -> 3389075.7 | M30: =(F30-L30)*J30 -> 410078.16 | N30: 1888816.6
B31: 44743 | C31: Petrobras | D31: 5107 | E31: 299225 | F31: 1448539.8 | G31: =F31-SUM(L31:N31) -> 1156805.3 | H31: =+IF(G31=0,0,G31/E31) -> 3.8660049 | I31: 0.12 | J31: 0.0165 | K31: 0.076 | L31: =+I31*F31 -> 173824.77 | M31: =(F31-L31)*J31 -> 21032.797 | N31: 96876.89
B32: 44743 | C32: Petrobras | D32: 5108 | E32: 9474983 | F32: 29170027 | G32: =F32-SUM(L32:N32) -> 25669624 | H32: =+IF(G32=0,0,G32/E32) -> 2.7092 | I32: 0.12 | J32: 0 | K32: 0 | L32: =+I32*F32 -> 3500403.3 | M32: =(F32-L32)*J32 -> 0 | N32: =(F32-L32)*K32 -> 0
B33: 44743 | C33: Petrobras | D33: 5109 | E33: 288334 | F33: 1266703.7 | G33: =F33-SUM(L33:N33) -> 1114699.2 | H33: =+IF(G33=0,0,G33/E33) -> 3.866 | I33: 0.12 | J33: 0 | K33: 0 | L33: =+I33*F33 -> 152004.44 | M33: =(F33-L33)*J33 -> 0 | N33: =(F33-L33)*K33 -> 0
B34: 44743 | C34: Petrobras | D34: 3376 | E34: 6892 | F34: 23380.68 | G34: =F34-SUM(L34:N34) -> 18671.831 | H34: =+IF(G34=0,0,G34/E34) -> 2.7092036 | I34: 0.12 | J34: 0.0165 | K34: 0.076 | L34: =+I34*F34 -> 2805.6816 | M34: =(F34-L34)*J34 -> 339.48747 | N34: 1563.68
B35: 44743 | C35: Petrobras | D35: 3377 | E35: 108537 | F35: 334145.94 | G35: =F35-SUM(L35:N35) -> 294048.43 | H35: =+IF(G35=0,0,G35/E35) -> 2.7091999 | I35: 0.12 | J35: 0 | K35: 0 | L35: =+I35*F35 -> 40097.513 | M35: =(F35-L35)*J35 -> 0 | N35: =(F35-L35)*K35 -> 0
B36: 44743 | C36: Petrobras | D36: 5068 | E36: 163676 | F36: 555260.48 | G36: =F36-SUM(L36:N36) -> 443431.57 | H36: =+IF(G36=0,0,G36/E36) -> 2.7092034 | I36: 0.12 | J36: 0.0165 | K36: 0.076 | L36: =+I36*F36 -> 66631.258 | M36: =(F36-L36)*J36 -> 8062.3822 | N36: 37135.27
B37: 44743 | C37: Petrobras | D37: 5069 | E37: 59942 | F37: 184539.63 | G37: =F37-SUM(L37:N37) -> 162394.87 | H37: =+IF(G37=0,0,G37/E37) -> 2.7092001 | I37: 0.12 | J37: 0 | K37: 0 | L37: =+I37*F37 -> 22144.756 | M37: =(F37-L37)*J37 -> 0 | N37: =(F37-L37)*K37 -> 0
B38: 44743 | C38: Shell | D38: 257517 | E38: -7270 | F38: -16838.05 | G38: =F38-SUM(L38:N38) -> -14210.893 | H38: =+IF(G38=0,0,G38/E38) -> 1.9547308 | I38: 0.07 | J38: 0.0165 | K38: 0.076 | L38: =+I38*F38 -> -1178.6635 | M38: =(F38-L38)*J38 -> -258.37988 | N38: =(F38-L38)*K38 -> -1190.1134
B39: 44743 | C39: Shell | D39: 257516 | E39: -11 | F39: -22.42 | G39: =F39-SUM(L39:N39) -> -18.92192 | H39: =+IF(G39=0,0,G39/E39) -> 1.7201745 | I39: 0.07 | J39: 0.0165 | K39: 0.076 | L39: =+I39*F39 -> -1.5694 | M39: =(F39-L39)*J39 -> -0.3440349 | N39: =(F39-L39)*K39 -> -1.5846456
B40: 44743 | C40: Shell | D40: 99 | E40: 24845885 | F40: 57545554 | G40: =F40-SUM(L40:N40) -> 48567009 | H40: =+IF(G40=0,0,G40/E40) -> 1.9547305 | I40: 0.07 | J40: 0.0165 | K40: 0.076 | L40: =+I40*F40 -> 4028188.8 | M40: =(F40-L40)*J40 -> 883036.53 | N40: =(F40-L40)*K40 -> 4067319.8
B41: 44743 | C41: New Fortress (Petrolina) | D41: 18-1 | E41: =291501+336567 -> 628068 | F41: 3174339.1 | G41: =F41-SUM(L41:N41) -> 2362184.4 | H41: =+IF(G41=0,0,G41/E41) -> 3.7610329 | I41: 0.18 | J41: 0.0165 | K41: 0.076 | L41: =+I41*F41 -> 571381.04 | M41: =20482.42+22466.39 -> 42948.81 | N41: =94343.27+103481.55 -> 197824.82
B42: 44743 | C42: New Fortress (Garanhuns) | D42: 19-1 | E42: =28223+45126 -> 73349 | F42: 360140.95 | G42: =F42-SUM(L42:N42) -> 267998.89 | H42: =+IF(G42=0,0,G42/E42) -> 3.6537497 | I42: 0.18 | J42: 0.0165 | K42: 0.076 | L42: =+I42*F42 -> 64825.371 | M42: =(F42-L42)*J42 -> 4872.7071 | N42: =(F42-L42)*K42 -> 22443.984
E45: =SUM(E18:E44) -> 51051841 | G45: =SUM(G18:G44) -> 1.2120124e+08
B48: Observações Relevantes: Publicação da Lei Complementar 194/2022, no DOU de 23.06.2022, Edição Extra, prevendo, até 31.12.2022, redução a zero da alíquota de PIS/COFINS incidente sobre a receita ou o faturamento na venda de gás natural veicular classificado nos códigos 2711.11.00 ou 2711.21.00 da NCM. "Art. 9º-B Até 31 de dezembro de 2022, ficam reduzidas a 0 (zero) as alíquotas das contribuições de que tratam o caput e o § 1º do art. 9º desta Lei Complementar incidentes sobre a receita ou o faturamento na venda ou sobre a importação de gás natural veicular classificado nos códigos 2711.11.00 ou 2711.21.00 da NCM." Dessa forma, a Copergás informou a Petrobras todo o volume de GNV e GNC veicular comercializado durante o mês de julho/22, o qual foi sensibilizado nas notas do supridor e, consequentemente, foram emitidas com alíquotas zero de PIS/Cofins Além disso, houve a necessidade de emissão por parte da Copergás da emissão de 2 notas de devolução para regularização das notas fiscais emitidas pela Shell em abril e maio/22.

Sheet ago22
C2: RELATÓRIO MENSAL DE ACOMPANHAMENTO DO CUSTO DO GÁS
C3: 44774
C5: Petrobras | D5: =SUMIF($C$18:$G$39,$C$5:$C$7,$G$18:$G$39)/SUMIF($C$18:$G$39,$C$5:$C$7,$E$18:$E$39) -> 2.8424561
C6: Shell | D6: =SUMIF($C$18:$G$39,$C$5:$C$7,$G$18:$G$39)/SUMIF($C$18:$G$39,$C$5:$C$7,$E$18:$E$39) -> 2.2936709
C7: NFE | D7: =SUM(G40:G41)/SUM(E40:E41) -> 3.9387137
M8: Poderação QDC | N8: Poderação QDR
C9: Custo Médio Ponderado real | D9: =+G44/E44 -> 2.5950619 | L9: =+C5 -> Petrobras | M9: =790000/1580000 -> 0.5 | N9: =+SUM(E18:E36)/E44 -> 0.49740843
L10: =+C6 -> Shell | M10: 0.47468354 | N10: =+SUM(E37:E39)/E44 -> 0.48531502
C11: Custo Médio Ponderado tarifa | D11: 2.5881 | L11: =+C7 -> NFE | M11: 0.025316456 | N11: =+SUM(E40:E41)/E44 -> 0.017276549
L12: Total | M12: =SUM(M9:M11) -> 1 | N12: =SUM(N9:N11) -> 1
L16: CONFORME XML DA NOTA
B17: Mês | C17: Supridor | D17: Nota Fiscal | E17: Vol m³ | F17: Compra R$ c/tributos | G17: Compra R$ s/tributos | H17: Custo | I17: ICMS | J17: PIS | K17: COFINS | L17: ICMS | M17: PIS | N17: COFINS
B18: 44774 | C18: Petrobras | D18: 430938-2 | E18: 49820 | F18: 166718.95 | G18: =F18-SUM(L18:N18) -> 140706.79 | H18: =+IF(G18=0,0,G18/E18) -> 2.8243034 | I18: 0.07 | J18: 0.0165 | K18: 0.076 | L18: =+I18*F18 -> 11670.327 | M18: 2558.3 | N18: 11783.53
B19: =B18 -> 44774 | C19: Petrobras | D19: 11063-6 | E19: 1765563 | F19: 6244026.5 | G19: =F19-SUM(L19:N19) -> 4986485.8 | H19: =+IF(G19=0,0,G19/E19) -> 2.8243035 | I19: 0.12 | J19: 0.0165 | K19: 0.076 | L19: =+I19*F19 -> 749283.18 | M19: 90663.27 | N19: 417594.25
B20: =B19 -> 44774 | C20: Petrobras | D20: 3612-12 | E20: 782661 | F20: 2767930.7 | G20: =F20-SUM(L20:N20) -> 2210472.2 | H20: =+IF(G20=0,0,G20/E20) -> 2.8243035 | I20: 0.12 | J20: 0.0165 | K20: 0.076 | L20: =+I20*F20 -> 332151.68 | M20: 40190.35 | N20: 185116.44
B21: =B20 -> 44774 | C21: Petrobras | D21: 5174-4 | E21: 7429162 | F21: 26273707 | G21: =F21-SUM(L21:N21) -> 20982209 | H21: =+IF(G21=0,0,G21/E21) -> 2.8243035 | I21: 0.12 | J21: 0.0165 | K21: 0.076 | L21: =+I21*F21 -> 3152844.8 | M21: 381494.22 | N21: 1757159.2
B22: =B21 -> 44774 | C22: Petrobras | D22: 3609-12 | E22: 33788 | F22: 170869.3 | G22: =F22-SUM(L22:N22) -> 136456.39 | H22: =+IF(G22=0,0,G22/E22) -> 4.0386052 | I22: 0.12 | J22: 0.0165 | K22: 0.076 | L22: =+I22*F22 -> 20504.316 | M22: 2481.02 | N22: 11427.57
B23: =B22 -> 44774 | C23: Petrobras | D23: 11064-6 | E23: 51566 | F23: 260774.42 | G23: =F23-SUM(L23:N23) -> 208254.72 | H23: =+IF(G23=0,0,G23/E23) -> 4.0386053 | I23: 0.12 | J23: 0.0165 | K23: 0.076 | L23: =+I23*F23 -> 31292.93 | M23: 3786.44 | N23: 17440.33
B24: =B23 -> 44774 | C24: Petrobras | D24: 5175-4 | E24: 88538 | F24: 447745.52 | G24: =F24-SUM(L24:N24) -> 357570.03 | H24: =+IF(G24=0,0,G24/E24) -> 4.0386052 | I24: 0.12 | J24: 0.0165 | K24: 0.076 | L24: =+I24*F24 -> 53729.462 | M24: 6501.26 | N24: 29944.77
B25: =B24 -> 44774 | C25: Petrobras | D25: 430939-2 | E25: 78616 | F25: 238747.49 | G25: =F25-SUM(L25:N25) -> 222035.17 | H25: =+IF(G25=0,0,G25/E25) -> 2.8243 | I25: 0.07 | J25: 0 | K25: 0 | L25: =+I25*F25 -> 16712.324 | M25: 0 | N25: 0
B26: =B25 -> 44774 | C26: Petrobras | D26: 11065-6 | E26: 2168885 | F26: 6960888.5 | G26: =F26-SUM(L26:N26) -> 6125581.9 | H26: =+IF(G26=0,0,G26/E26) -> 2.8243 | I26: 0.12 | J26: 0 | K26: 0 | L26: =+I26*F26 -> 835306.62 | M26: 0 | N26: 0
B27: =B26 -> 44774 | C27: Petrobras | D27: 5176-4 | E27: 11016082 | F27: 35355364 | G27: =F27-SUM(L27:N27) -> 31112720 | H27: =+IF(G27=0,0,G27/E27) -> 2.8243 | I27: 0.12 | J27: 0 | K27: 0 | L27: =+I27*F27 -> 4242643.7 | M27: 0 | N27: 0
B28: =B27 -> 44774 | C28: Petrobras | D28: 3610-12 | E28: 876339 | F28: 2812550.3 | G28: =F28-SUM(L28:N28) -> 2475044.2 | H28: =+IF(G28=0,0,G28/E28) -> 2.8243 | I28: 0.12 | J28: 0 | K28: 0 | L28: =+I28*F28 -> 337506.03 | M28: 0 | N28: 0
B29: =B28 -> 44774 | C29: Petrobras | D29: 11066-6 | E29: 59053 | F29: 271013.01 | G29: =F29-SUM(L29:N29) -> 238491.45 | H29: =+IF(G29=0,0,G29/E29) -> 4.0386001 | I29: 0.12 | J29: 0 | K29: 0 | L29: =+I29*F29 -> 32521.561 | M29: 0 | N29: 0
B30: =B29 -> 44774 | C30: Petrobras | D30: 5177-4 | E30: 96350 | F30: 442180.81 | G30: =F30-SUM(L30:N30) -> 389119.11 | H30: =+IF(G30=0,0,G30/E30) -> 4.0386 | I30: 0.12 | J30: 0 | K30: 0 | L30: =+I30*F30 -> 53061.697 | M30: 0 | N30: 0
B31: =B30 -> 44774 | C31: Petrobras | D31: 3611-12 | E31: 37505 | F31: 172122.38 | G31: =F31-SUM(L31:N31) -> 151467.69 | H31: =+IF(G31=0,0,G31/E31) -> 4.0386 | I31: 0.12 | J31: 0 | K31: 0 | L31: =+I31*F31 -> 20654.686 | M31: 0 | N31: 0
B32: =B31 -> 44774 | C32: Petrobras | G32: =F32-SUM(L32:N32) -> 0 | H32: =+IF(G32=0,0,G32/E32) -> 0 | L32: =+I32*F32 -> 0 | M32: =(F32-L32)*J32 -> 0 | N32: =(F32-L32)*K32 -> 0
B33: =B32 -> 44774 | C33: Petrobras | G33: =F33-SUM(L33:N33) -> 0 | H33: =+IF(G33=0,0,G33/E33) -> 0 | L33: =+I33*F33 -> 0 | M33: =(F33-L33)*J33 -> 0 | N33: =(F33-L33)*K33 -> 0
B34: =B33 -> 44774 | C34: Petrobras | G34: =F34-SUM(L34:N34) -> 0 | H34: =+IF(G34=0,0,G34/E34) -> 0 | L34: =+I34*F34 -> 0 | M34: =(F34-L34)*J34 -> 0 | N34: =(F34-L34)*K34 -> 0
B35: =B34 -> 44774 | C35: Petrobras | G35: =F35-SUM(L35:N35) -> 0 | H35: =+IF(G35=0,0,G35/E35) -> 0 | L35: =+I35*F35 -> 0 | M35: =(F35-L35)*J35 -> 0 | N35: =(F35-L35)*K35 -> 0
B36: =B35 -> 44774 | C36: Petrobras | G36: =F36-SUM(L36:N36) -> 0 | H36: =+IF(G36=0,0,G36/E36) -> 0 | L36: =+I36*F36 -> 0 | M36: =(F36-L36)*J36 -> 0 | N36: =(F36-L36)*K36 -> 0
B37: =B36 -> 44774 | C37: Shell | G37: =F37-SUM(L37:N37) -> 0 | H37: =+IF(G37=0,0,G37/E37) -> 0 | J37: 0.0165 | K37: 0.076
B38: =B37 -> 44774 | C38: Shell | G38: =F38-SUM(L38:N38) -> 0 | H38: =+IF(G38=0,0,G38/E38) -> 0 | J38: 0.0165 | K38: 0.076
B39: =B38 -> 44774 | C39: Shell | D39: 221-1 | E39: 23937439 | F39: 65054778 | G39: =F39-SUM(L39:N39) -> 54904606 | H39: =+IF(G39=0,0,G39/E39) -> 2.2936709 | I39: 0.07 | J39: 0.0165 | K39: 0.076 | L39: =+I39*F39 -> 4553834.5 | M39: 998265.57 | N39: 4598071.7
B40: =B39 -> 44774 | C40: New Fortress (Petrolina) | D40: 21-1 | E40: =625673+153041 -> 778714 | F40: 4130352.9 | G40: =F40-SUM(L40:N40) -> 3073602.1 | H40: =+IF(G40=0,0,G40/E40) -> 3.9470231 | I40: 0.18 | J40: 0.0165 | K40: 0.076 | L40: =+I40*F40 -> 743463.52 | M40: 55883.67 | N40: 257403.59
B41: =B40 -> 44774 | C41: New Fortress (Garanhuns) | D41: 21-1 | E41: =58033+15393 -> 73426 | F41: 379941.32 | G41: =F41-SUM(L41:N41) -> 282733.34 | H41: =+IF(G41=0,0,G41/E41) -> 3.8505889 | I41: 0.18 | J41: 0.0165 | K41: 0.076 | L41: 68389.43 | M41: 5140.61 | N41: 23677.94
E44: =SUM(E18:E43) -> 49323507 | G44: =SUM(G18:G43) -> 1.2799756e+08
B47: Observações Relevantes: Publicação da Lei Complementar 194/2022, no DOU de 23.06.2022, Edição Extra, prevendo, até 31.12.2022, redução a zero da alíquota de PIS/COFINS incidente sobre a receita ou o faturamento na venda de gás natural veicular classificado nos códigos 2711.11.00 ou 2711.21.00 da NCM. "Art. 9º-B Até 31 de dezembro de 2022, ficam reduzidas a 0 (zero) as alíquotas das contribuições de que tratam o caput e o § 1º do art. 9º desta Lei Complementar incidentes sobre a receita ou o faturamento na venda ou sobre a importação de gás natural veicular classificado nos códigos 2711.11.00 ou 2711.21.00 da NCM." Dessa forma, a Copergás informou a Petrobras todo o volume de GNV e GNC veicular comercializado durante o mês de julho/22, o qual foi sensibilizado nas notas do supridor e, consequentemente, foram emitidas com alíquotas zero de PIS/Cofins NewFortress - GARANHUNS: Desconto de 5% do Preço do Gás, sobre o volume de 15.393 m³, pelo não cumprimento da estocagem mínima prevista em contrato (cláusula 6.2.4.). NewFortress - PETROLINA: Desconto de 5% do Preço do Gás, sobre o volume de 153.041m³, pelo não cumprimento da estocagem mínima prevista em contrato (cláusula 6.2.4.).

Sheet set22
C2: RELATÓRIO MENSAL DE ACOMPANHAMENTO DO CUSTO DO GÁS
C3: 44805
C5: Petrobras | D5: =SUMIF($C$18:$G$41,$C$5:$C$7,$G$18:$G$41)/SUMIF($C$18:$G$41,$C$5:$C$7,$E$18:$E$41) -> 2.8371809
C6: Shell | D6: =SUMIF($C$18:$G$41,$C$5:$C$7,$G$18:$G$41)/SUMIF($C$18:$G$41,$C$5:$C$7,$E$18:$E$41) -> 2.2936709
C7: NFE | D7: =SUM(G42:G43)/SUM(E42:E43) -> 3.9776824
M8: Poderação QDC | N8: Poderação QDR
C9: Custo Médio Ponderado real | D9: =+G46/E46 -> 2.5732966 | L9: =+C5 -> Petrobras | M9: =790000/1580000 -> 0.5 | N9: =+SUM(E18:E36)/E46 -> 0.46571209
L10: =+C6 -> Shell | M10: 0.47468354 | N10: =+SUM(E39:E41)/E46 -> 0.51841141
C11: Custo Médio Ponderado tarifa | D11: 2.5881 | L11: =+C7 -> NFE | M11: 0.025316456 | N11: =+SUM(E42:E43)/E46 -> 0.015675117
L12: Total | M12: =SUM(M9:M11) -> 1 | N12: =SUM(N9:N11) -> 0.99979861
L16: CONFORME XML DA NOTA
B17: Mês | C17: Supridor | D17: Nota Fiscal | E17: Vol m³ | F17: Compra R$ c/tributos | G17: Compra R$ s/tributos | H17: Custo | I17: ICMS | J17: PIS | K17: COFINS | L17: ICMS | M17: PIS | N17: COFINS
B18: 44805 | C18: Petrobras | D18: 11181-6 | E18: 931775 | F18: 3295281.9 | G18: =F18-SUM(L18:N18) -> 2631615.4 | H18: =+IF(G18=0,0,G18/E18) -> 2.8243035 | I18: 0.12 | J18: 0.0165 | K18: 0.076 | L18: =+I18*F18 -> 395433.83 | M18: 47847.49 | N18: 220385.16
B19: =B18 -> 44805 | C19: Petrobras | D19: 431038-2 | E19: 154512 | F19: 517062.99 | G19: =F19-SUM(L19:N19) -> 436388.75 | H19: =+IF(G19=0,0,G19/E19) -> 2.8243033 | I19: 0.07 | J19: 0.0165 | K19: 0.076 | L19: =+I19*F19 -> 36194.409 | M19: 7934.33 | N19: 36545.5
B20: =B19 -> 44805 | C20: Petrobras | D20: 3427-28 | E20: 57232 | F20: 202404.63 | G20: =F20-SUM(L20:N20) -> 161640.53 | H20: =+IF(G20=0,0,G20/E20) -> 2.8243034 | I20: 0.12 | J20: 0.0165 | K20: 0.076 | L20: =+I20*F20 -> 24288.556 | M20: 2938.92 | N20: 13536.62
B21: =B20 -> 44805 | C21: Petrobras | D21: 5161-24 | E21: 620441 | F21: 2194229.3 | G21: =F21-SUM(L21:N21) -> 1752313.7 | H21: =+IF(G21=0,0,G21/E21) -> 2.8243035 | I21: 0.12 | J21: 0.0165 | K21: 0.076 | L21: =+I21*F21 -> 263307.52 | M21: 31860.21 | N21: 146747.86
B22: =B21 -> 44805 | C22: Petrobras | D22: 5255-4 | E22: 9069958 | F22: 32076487 | G22: =F22-SUM(L22:N22) -> 25616314 | H22: =+IF(G22=0,0,G22/E22) -> 2.8243035 | I22: 0.12 | J22: 0.0165 | K22: 0.076 | L22: =+I22*F22 -> 3849178.4 | M22: 465750.59 | N22: 2145243.4
A23: PGU1 | B23: =B22 -> 44805 | C23: Petrobras | D23: 5256-4 | E23: 58832 | F23: 297519.31 | G23: =F23-SUM(L23:N23) -> 237599.22 | H23: =+IF(G23=0,0,G23/E23) -> 4.0386052 | I23: 0.12 | J23: 0.0165 | K23: 0.076 | L23: =+I23*F23 -> 35702.317 | M23: 4319.98 | N23: 19897.79
A24: PGU1 | B24: =B23 -> 44805 | C24: Petrobras | D24: 5162-24 | E24: 23610 | F24: 119398.13 | G24: =F24-SUM(L24:N24) -> 95351.464 | H24: =+IF(G24=0,0,G24/E24) -> 4.038605 | I24: 0.12 | J24: 0.0165 | K24: 0.076 | L24: =+I24*F24 -> 14327.776 | M24: 1733.66 | N24: 7985.23
A25: GNV | B25: =B24 -> 44805 | C25: Petrobras | D25: 5257-4 | E25: 11048991 | F25: 35460983 | G25: =F25-SUM(L25:N25) -> 31205665 | H25: =+IF(G25=0,0,G25/E25) -> 2.8243 | I25: 0.12 | J25: 0 | K25: 0 | L25: =+I25*F25 -> 4255318 | M25: 0 | N25: 0
A26: GNV | B26: =B25 -> 44805 | C26: Petrobras | D26: 5163-24 | E26: 829476 | F26: 2662146.7 | G26: =F26-SUM(L26:N26) -> 2342689.1 | H26: =+IF(G26=0,0,G26/E26) -> 2.8243 | I26: 0.12 | J26: 0 | K26: 0 | L26: =+I26*F26 -> 319457.6 | M26: 0 | N26: 0
A27: GNV | B27: =B26 -> 44805 | C27: Petrobras | D27: 431037-2 | E27: 236824.77 | F27: 719208.82 | G27: =F27-SUM(L27:N27) -> 668864.2 | H27: =+IF(G27=0,0,G27/E27) -> 2.8243 | I27: 0.07 | J27: 0 | K27: 0 | L27: =+I27*F27 -> 50344.617 | M27: 0 | N27: 0
A28: GNV | B28: =B27 -> 44805 | C28: Petrobras | D28: 431036-2 | E28: 53023.229 | F28: 161025.28 | G28: =F28-SUM(L28:N28) -> 149753.51 | H28: =+IF(G28=0,0,G28/E28) -> 2.8243001 | I28: 0.07 | J28: 0 | K28: 0 | L28: =+I28*F28 -> 11271.77 | M28: 0 | N28: 0
A29: GNV | B29: =B28 -> 44805 | C29: Petrobras | D29: 11183-6 | E29: 1026055 | F29: 3293053.6 | G29: =F29-SUM(L29:N29) -> 2897887.1 | H29: =+IF(G29=0,0,G29/E29) -> 2.8243 | I29: 0.12 | J29: 0 | K29: 0 | L29: =+I29*F29 -> 395166.43 | M29: 0 | N29: 0
A30: PGU1 GNV | B30: =B29 -> 44805 | C30: Petrobras | D30: 431035-2 | E30: 10196 | F30: 44276.96 | G30: =F30-SUM(L30:N30) -> 41177.573 | H30: =+IF(G30=0,0,G30/E30) -> 4.0386007 | I30: 0.07 | J30: 0 | K30: 0 | L30: =+I30*F30 -> 3099.3872 | M30: 0 | N30: 0
A31: PGU1 GNV | B31: =B30 -> 44805 | C31: Petrobras | D31: 5258-4 | E31: 76482 | F31: 351000.24 | G31: =F31-SUM(L31:N31) -> 308880.21 | H31: =+IF(G31=0,0,G31/E31) -> 4.0386001 | I31: 0.12 | J31: 0 | K31: 0 | L31: =+I31*F31 -> 42120.029 | M31: 0 | N31: 0
A32: PGU1 GNV | B32: =B31 -> 44805 | C32: Petrobras | D32: 5164-24 | E32: 24647 | F32: 113112.92 | G32: =F32-SUM(L32:N32) -> 99539.37 | H32: =+IF(G32=0,0,G32/E32) -> 4.0385998 | I32: 0.12 | J32: 0 | K32: 0 | L32: =+I32*F32 -> 13573.55 | M32: 0 | N32: 0
A33: PGU1 GNV | B33: =B32 -> 44805 | C33: Petrobras | D33: 11184-6 | E33: 17182 | F33: 78853.67 | G33: =F33-SUM(L33:N33) -> 69391.23 | H33: =+IF(G33=0,0,G33/E33) -> 4.0386003 | I33: 0.12 | J33: 0 | K33: 0 | L33: =+I33*F33 -> 9462.4404 | M33: 0 | N33: 0
A34: PGU1 | B34: =B33 -> 44805 | C34: Petrobras | D34: 431034-2 | E34: 6901 | F34: 33022.76 | G34: =F34-SUM(L34:N34) -> 27870.417 | H34: =+IF(G34=0,0,G34/E34) -> 4.0386055 | I34: 0.07 | J34: 0.0165 | K34: 0.076 | L34: =+I34*F34 -> 2311.5932 | M34: 506.73 | N34: 2334.02
... A38: PGU1 | B38: =B37 -> 44805 | C38: Petrobras | D38: 3428-28 | E38: 2947 | F38: 14903.27 | G38: =F38-SUM(L38:N38) -> 11901.758 | H38: =+IF(G38=0,0,G38/E38) -> 4.0386012 | I38: 0.12 | J38: 0.0165 | K38: 0.076 | L38: =+I38*F38 -> 1788.3924 | M38: 216.4 | N38: 996.72
B39: =B36 -> 44805 | C39: Shell | G39: =F39-SUM(L39:N39) -> 0 | H39: =+IF(G39=0,0,G39/E39) -> 0 | J39: 0.0165 | K39: 0.076 | L39: =+I39*F39 -> 0
B40: =B39 -> 44805 | C40: Shell | D40: 224-1 | E40: 27183472 | F40: 73876522 | G40: =F40-SUM(L40:N40) -> 62349938 | H40: =+IF(G40=0,0,G40/E40) -> 2.2936709 | I40: 0.07 | J40: 0.0165 | K40: 0.076 | L40: =+I40*F40 -> 5171356.5 | M40: 1133635.2 | N40: 5221592.6
B41: =B40 -> 44805 | C41: Shell | G41: =F41-SUM(L41:N41) -> 0 | H41: =+IF(G41=0,0,G41/E41) -> 0 | J41: 0.0165 | K41: 0.076 | L41: =+I41*F41 -> 0
B42: =B41 -> 44805 | C42: New Fortress (Petrolina) | D42: 22-1 | E42: 748197 | F42: 4007866.9 | G42: =F42-SUM(L42:N42) -> 2982454.1 | H42: =+IF(G42=0,0,G42/E42) -> 3.9861883 | I42: 0.18 | J42: 0.0165 | K42: 0.076 | L42: =+I42*F42 -> 721416.04 | M42: 54226.44 | N42: 249770.26
B43: =B42 -> 44805 | C43: New Fortress (Garanhuns) | D43: 22-1 | E43: 73745 | F43: 385634.73 | G43: =F43-SUM(L43:N43) -> 286970.08 | H43: =+IF(G43=0,0,G43/E43) -> 3.8913835 | I43: 0.18 | J43: 0.0165 | K43: 0.076 | L43: =+I43*F43 -> 69414.251 | M43: 5217.64 | N43: 24032.76
E46: =SUM(E18:E45) -> 52436099 | G46: =SUM(G18:G45) -> 1.3493363e+08
B49: Observações Relevantes: Publicação da Lei Complementar 194/2022, no DOU de 23.06.2022, Edição Extra, prevendo, até 31.12.2022, redução a zero da alíquota de PIS/COFINS incidente sobre a receita ou o faturamento na venda de gás natural veicular classificado nos códigos 2711.11.00 ou 2711.21.00 da NCM. "Art. 9º-B Até 31 de dezembro de 2022, ficam reduzidas a 0 (zero) as alíquotas das contribuições de que tratam o caput e o § 1º do art. 9º desta Lei Complementar incidentes sobre a receita ou o faturamento na venda ou sobre a importação de gás natural veicular classificado nos códigos 2711.11.00 ou 2711.21.00 da NCM." Dessa forma, a Copergás informou a Petrobras todo o volume de GNV e GNC veicular comercializado durante o mês de julho/22, o qual foi sensibilizado nas notas do supridor e, consequentemente, foram emitidas com alíquotas zero de PIS/Cofins

Sheet Out22
C2: RELATÓRIO MENSAL DE ACOMPANHAMENTO DO CUSTO DO GÁS
C3: 44835
C5: Petrobras | D5: =SUMIF($C$18:$G$41,$C$5:$C$7,$G$18:$G$41)/SUMIF($C$18:$G$41,$C$5:$C$7,$E$18:$E$41) -> 2.8279084
